[2024-04-24T09:36:40.493+0000] {taskinstance.py:1979} INFO - Dependencies all met for dep_context=non-requeueable deps ti=<TaskInstance: download_rocket_launches.get_pictures manual__2024-04-24T09:36:36.759557+00:00 [queued]>
[2024-04-24T09:36:40.497+0000] {taskinstance.py:1979} INFO - Dependencies all met for dep_context=requeueable deps ti=<TaskInstance: download_rocket_launches.get_pictures manual__2024-04-24T09:36:36.759557+00:00 [queued]>
[2024-04-24T09:36:40.497+0000] {taskinstance.py:2193} INFO - Starting attempt 1 of 1
[2024-04-24T09:36:40.504+0000] {taskinstance.py:2217} INFO - Executing <Task(PythonOperator): get_pictures> on 2024-04-24 09:36:36.759557+00:00
[2024-04-24T09:36:40.508+0000] {standard_task_runner.py:60} INFO - Started process 368 to run task
[2024-04-24T09:36:40.509+0000] {standard_task_runner.py:87} INFO - Running: ['***', 'tasks', 'run', 'download_rocket_launches', 'get_pictures', 'manual__2024-04-24T09:36:36.759557+00:00', '--job-id', '13', '--raw', '--subdir', 'DAGS_FOLDER/Example_dag.py', '--cfg-path', '/tmp/tmpbl3gzmf8']
[2024-04-24T09:36:40.510+0000] {standard_task_runner.py:88} INFO - Job 13: Subtask get_pictures
[2024-04-24T09:36:40.534+0000] {task_command.py:423} INFO - Running <TaskInstance: download_rocket_launches.get_pictures manual__2024-04-24T09:36:36.759557+00:00 [running]> on host 99514668da53
[2024-04-24T09:36:40.566+0000] {taskinstance.py:2513} INFO - Exporting env vars: AIRFLOW_CTX_DAG_OWNER='***' AIRFLOW_CTX_DAG_ID='download_rocket_launches' AIRFLOW_CTX_TASK_ID='get_pictures' AIRFLOW_CTX_EXECUTION_DATE='2024-04-24T09:36:36.759557+00:00' AIRFLOW_CTX_TRY_NUMBER='1' AIRFLOW_CTX_DAG_RUN_ID='manual__2024-04-24T09:36:36.759557+00:00'
[2024-04-24T09:36:40.567+0000] {taskinstance.py:2731} ERROR - Task failed with exception
Traceback (most recent call last):
  File "/home/airflow/.local/lib/python3.8/site-packages/airflow/models/taskinstance.py", line 444, in _execute_task
    result = _execute_callable(context=context, **execute_callable_kwargs)
  File "/home/airflow/.local/lib/python3.8/site-packages/airflow/models/taskinstance.py", line 414, in _execute_callable
    return execute_callable(context=context, **execute_callable_kwargs)
  File "/home/airflow/.local/lib/python3.8/site-packages/airflow/operators/python.py", line 200, in execute
    return_value = self.execute_callable()
  File "/home/airflow/.local/lib/python3.8/site-packages/airflow/operators/python.py", line 217, in execute_callable
    return self.python_callable(*self.op_args, **self.op_kwargs)
  File "/opt/airflow/dags/Example_dag.py", line 28, in _get_pictures
    with open("launches.json") as f:
FileNotFoundError: [Errno 2] No such file or directory: 'launches.json'
[2024-04-24T09:36:40.571+0000] {taskinstance.py:1149} INFO - Marking task as FAILED. dag_id=download_rocket_launches, task_id=get_pictures, execution_date=20240424T093636, start_date=20240424T093640, end_date=20240424T093640
[2024-04-24T09:36:40.576+0000] {standard_task_runner.py:107} ERROR - Failed to execute job 13 for task get_pictures ([Errno 2] No such file or directory: 'launches.json'; 368)
[2024-04-24T09:36:40.601+0000] {local_task_job_runner.py:234} INFO - Task exited with return code 1
[2024-04-24T09:36:40.613+0000] {taskinstance.py:3312} INFO - 0 downstream tasks scheduled from follow-on schedule check
