[2024-04-24T09:44:31.481+0000] {taskinstance.py:1979} INFO - Dependencies all met for dep_context=non-requeueable deps ti=<TaskInstance: download_rocket_launches.get_pictures manual__2024-04-24T09:44:27.583162+00:00 [queued]>
[2024-04-24T09:44:31.486+0000] {taskinstance.py:1979} INFO - Dependencies all met for dep_context=requeueable deps ti=<TaskInstance: download_rocket_launches.get_pictures manual__2024-04-24T09:44:27.583162+00:00 [queued]>
[2024-04-24T09:44:31.486+0000] {taskinstance.py:2193} INFO - Starting attempt 1 of 1
[2024-04-24T09:44:31.493+0000] {taskinstance.py:2217} INFO - Executing <Task(PythonOperator): get_pictures> on 2024-04-24 09:44:27.583162+00:00
[2024-04-24T09:44:31.496+0000] {standard_task_runner.py:60} INFO - Started process 508 to run task
[2024-04-24T09:44:31.498+0000] {standard_task_runner.py:87} INFO - Running: ['***', 'tasks', 'run', 'download_rocket_launches', 'get_pictures', 'manual__2024-04-24T09:44:27.583162+00:00', '--job-id', '17', '--raw', '--subdir', 'DAGS_FOLDER/Example_dag.py', '--cfg-path', '/tmp/tmpx1w79vq1']
[2024-04-24T09:44:31.499+0000] {standard_task_runner.py:88} INFO - Job 17: Subtask get_pictures
[2024-04-24T09:44:31.522+0000] {task_command.py:423} INFO - Running <TaskInstance: download_rocket_launches.get_pictures manual__2024-04-24T09:44:27.583162+00:00 [running]> on host 99514668da53
[2024-04-24T09:44:31.555+0000] {taskinstance.py:2513} INFO - Exporting env vars: AIRFLOW_CTX_DAG_OWNER='***' AIRFLOW_CTX_DAG_ID='download_rocket_launches' AIRFLOW_CTX_TASK_ID='get_pictures' AIRFLOW_CTX_EXECUTION_DATE='2024-04-24T09:44:27.583162+00:00' AIRFLOW_CTX_TRY_NUMBER='1' AIRFLOW_CTX_DAG_RUN_ID='manual__2024-04-24T09:44:27.583162+00:00'
[2024-04-24T09:44:31.555+0000] {taskinstance.py:2731} ERROR - Task failed with exception
Traceback (most recent call last):
  File "/home/airflow/.local/lib/python3.8/site-packages/airflow/models/taskinstance.py", line 444, in _execute_task
    result = _execute_callable(context=context, **execute_callable_kwargs)
  File "/home/airflow/.local/lib/python3.8/site-packages/airflow/models/taskinstance.py", line 414, in _execute_callable
    return execute_callable(context=context, **execute_callable_kwargs)
  File "/home/airflow/.local/lib/python3.8/site-packages/airflow/operators/python.py", line 200, in execute
    return_value = self.execute_callable()
  File "/home/airflow/.local/lib/python3.8/site-packages/airflow/operators/python.py", line 217, in execute_callable
    return self.python_callable(*self.op_args, **self.op_kwargs)
  File "/opt/airflow/dags/Example_dag.py", line 28, in _get_pictures
    with open("/launches.json") as f:
FileNotFoundError: [Errno 2] No such file or directory: '/launches.json'
[2024-04-24T09:44:31.560+0000] {taskinstance.py:1149} INFO - Marking task as FAILED. dag_id=download_rocket_launches, task_id=get_pictures, execution_date=20240424T094427, start_date=20240424T094431, end_date=20240424T094431
[2024-04-24T09:44:31.565+0000] {standard_task_runner.py:107} ERROR - Failed to execute job 17 for task get_pictures ([Errno 2] No such file or directory: '/launches.json'; 508)
[2024-04-24T09:44:31.590+0000] {local_task_job_runner.py:234} INFO - Task exited with return code 1
[2024-04-24T09:44:31.602+0000] {taskinstance.py:3312} INFO - 0 downstream tasks scheduled from follow-on schedule check
