[2024-04-24T09:49:10.578+0000] {taskinstance.py:1979} INFO - Dependencies all met for dep_context=non-requeueable deps ti=<TaskInstance: download_rocket_launches.get_pictures manual__2024-04-24T09:49:07.177421+00:00 [queued]>
[2024-04-24T09:49:10.582+0000] {taskinstance.py:1979} INFO - Dependencies all met for dep_context=requeueable deps ti=<TaskInstance: download_rocket_launches.get_pictures manual__2024-04-24T09:49:07.177421+00:00 [queued]>
[2024-04-24T09:49:10.582+0000] {taskinstance.py:2193} INFO - Starting attempt 1 of 1
[2024-04-24T09:49:10.590+0000] {taskinstance.py:2217} INFO - Executing <Task(PythonOperator): get_pictures> on 2024-04-24 09:49:07.177421+00:00
[2024-04-24T09:49:10.594+0000] {standard_task_runner.py:60} INFO - Started process 590 to run task
[2024-04-24T09:49:10.596+0000] {standard_task_runner.py:87} INFO - Running: ['***', 'tasks', 'run', 'download_rocket_launches', 'get_pictures', 'manual__2024-04-24T09:49:07.177421+00:00', '--job-id', '20', '--raw', '--subdir', 'DAGS_FOLDER/Example_dag.py', '--cfg-path', '/tmp/tmp032u6mvp']
[2024-04-24T09:49:10.597+0000] {standard_task_runner.py:88} INFO - Job 20: Subtask get_pictures
[2024-04-24T09:49:10.697+0000] {task_command.py:423} INFO - Running <TaskInstance: download_rocket_launches.get_pictures manual__2024-04-24T09:49:07.177421+00:00 [running]> on host 99514668da53
[2024-04-24T09:49:10.733+0000] {taskinstance.py:2513} INFO - Exporting env vars: AIRFLOW_CTX_DAG_OWNER='***' AIRFLOW_CTX_DAG_ID='download_rocket_launches' AIRFLOW_CTX_TASK_ID='get_pictures' AIRFLOW_CTX_EXECUTION_DATE='2024-04-24T09:49:07.177421+00:00' AIRFLOW_CTX_TRY_NUMBER='1' AIRFLOW_CTX_DAG_RUN_ID='manual__2024-04-24T09:49:07.177421+00:00'
[2024-04-24T09:49:14.443+0000] {taskinstance.py:2731} ERROR - Task failed with exception
Traceback (most recent call last):
  File "/home/airflow/.local/lib/python3.8/site-packages/airflow/models/taskinstance.py", line 444, in _execute_task
    result = _execute_callable(context=context, **execute_callable_kwargs)
  File "/home/airflow/.local/lib/python3.8/site-packages/airflow/models/taskinstance.py", line 414, in _execute_callable
    return execute_callable(context=context, **execute_callable_kwargs)
  File "/home/airflow/.local/lib/python3.8/site-packages/airflow/operators/python.py", line 200, in execute
    return_value = self.execute_callable()
  File "/home/airflow/.local/lib/python3.8/site-packages/airflow/operators/python.py", line 217, in execute_callable
    return self.python_callable(*self.op_args, **self.op_kwargs)
  File "/opt/airflow/dags/Example_dag.py", line 36, in _get_pictures
    with open(target_file, "wb") as f:
FileNotFoundError: [Errno 2] No such file or directory: '/images/falcon2520925_image_20221009234147.png'
[2024-04-24T09:49:14.449+0000] {taskinstance.py:1149} INFO - Marking task as FAILED. dag_id=download_rocket_launches, task_id=get_pictures, execution_date=20240424T094907, start_date=20240424T094910, end_date=20240424T094914
[2024-04-24T09:49:14.455+0000] {standard_task_runner.py:107} ERROR - Failed to execute job 20 for task get_pictures ([Errno 2] No such file or directory: '/images/falcon2520925_image_20221009234147.png'; 590)
[2024-04-24T09:49:14.498+0000] {local_task_job_runner.py:234} INFO - Task exited with return code 1
[2024-04-24T09:49:14.510+0000] {taskinstance.py:3312} INFO - 0 downstream tasks scheduled from follow-on schedule check
